Workbook

Sheet Canales
A1: ID Grupo | B1: id | C1: channel_title | D1: channel_description | E1: link | F1: channel_viewcount | G1: channel_subscribercount | H1: channel_videocount | I1: id_video | J1: recent_id_video | K1: Excluded(Nico) | L1: No se ve | M1: Sacar del grupo | N1: Sacar del inventario | O1: Comentarios | P1: Categoria
A2: 0.0 | B2: UC88zpEpyV_wQR4MXO05xf2Q | C2: Full | D2: O seu canal sobre FUTEBOL REAL e FIFA :) | E2: www.youtube.com/@fullg | F2: 486517611 | G2: 2070000 | H2: 2925 | I2: 8IP8h5RN_0U | J2: MnC68TSwDro | K2: =VLOOKUP(B2,'Excluded(Nico)'!A:A,1,False) -> #REF! | L2: TRUE | M2: FALSE | N2: TRUE | O2: La url funciona con /c/@fullg, descartar | P2: =VLOOKUP(A2,Grupos!B:E,4,FALSE) -> #REF!
A3: 0.0 | B3: UCDoOmSJp3ks_r8hbt2f0Hbw | C3: pinguinFUT | D3: Bem-vindo ao PinguinFUT jogos ao vivo assista hoje o seu canal de futebol e simulação realista fifa/pes!futebol nunca é demais, e Nunca Será demais !Aqui você acompanha os melhores momentos e gols dos principais jogos de futebol do Brasil e do Mundo.INSCREVA-SE, E ATIVE AS NOTIFICAÇÕES! conto com vocês .... | E3: www.youtube.com/@pinguinfut | F3: 58971414 | G3: 325000 | H3: 6817 | I3: cI863jYCAa8 | J3: eIOrodurpNE | K3: =VLOOKUP(B3,'Excluded(Nico)'!A:A,1,False) -> #REF! | L3: FALSE | M3: FALSE | N3: FALSE | P3: =VLOOKUP(A3,Grupos!B:E,4,FALSE) -> #REF!
A4: 0.0 | B4: UCCG1YqDMys90MUZFOLxUw5A | C4: RC Football | D4: Canal destinado aos amantes do Futebol | E4: www.youtube.com/@rcfootball | F4: 31226799 | G4: 276000 | H4: 1329 | I4: l5gNv-QzgQ0 | J4: 2QzO0-V1mQM | K4: =VLOOKUP(B4,'Excluded(Nico)'!A:A,1,False) -> #REF! | L4: FALSE | M4: FALSE | N4: FALSE | P4: =VLOOKUP(A4,Grupos!B:E,4,FALSE) -> #REF!
A5: 0.0 | B5: UCSXflBePm_wxde5_csmmUbA | C5: Santos Masinha | D5: Email para contato: santosmasinha@nwb.com.br | E5: www.youtube.com/@santosmasinha | F5: channel_viewcount | G5: 166000 | H5: 264 | I5: QbKso5BJKgE | J5: JD63rGzWec0 | K5: =VLOOKUP(B5,'Excluded(Nico)'!A:A,1,False) -> #REF! | L5: FALSE | M5: FALSE | N5: FALSE | P5: =VLOOKUP(A5,Grupos!B:E,4,FALSE) -> #REF!
A6: 0.0 | B6: UCkhrtqLk3kMI3P7sP4DUmxg | C6: Boleiros Da Firma | E6: www.youtube.com/@boleirosdafirma | F6: 10849634 | G6: 109000 | H6: 208 | I6: 5OKgS7_EE1c | J6: Mg298bI6DDY | K6: =VLOOKUP(B6,'Excluded(Nico)'!A:A,1,False) -> #REF! | L6: FALSE | M6: FALSE | N6: FALSE | P6: =VLOOKUP(A6,Grupos!B:E,4,FALSE) -> #REF!
A7: 0.0 | B7: UC8lbGIAGM0JiA_yqQw_1PBA | C7: Doug Games | D7: Welcome to DGTV, the official channel of Doug Games, here you will find:Simulations of real matches recorded in Efootball PES 2021 and FIFA 23 on PC.GameplaysLivesAll videos posted on this channel are my own, any video taken without my permission will be subject to rights claims and the channel will be penalized.- Doug Games | E7: www.youtube.com/@douggames | F7: 63289634 | G7: 264000 | H7: 5141 | I7: -5zuFSQyocc | J7: XafxZG_SkKU | K7: =VLOOKUP(B7,'Excluded(Nico)'!A:A,1,False) -> #REF! | L7: FALSE | M7: FALSE | N7: FALSE | P7: =VLOOKUP(A7,Grupos!B:E,4,FALSE) -> #REF!
A8: 0.0 | B8: UCHIY759GkSeepw6pHzVCrng | C8: Afinco | D8: Olá, meu nome é Luis mas podem me chamar de Afinco!Esse canal foi feito para você, amante do Futebol que joga e estuda Cartola FC!Espero que se divirta assistindo meus vídeos!📱 Redes Sociais do Afinco:- Procure por Afinco e vai achar 🤡(Medo do youtube diminuir o alcance blz?)✉ Contato profissional:- Contatoafinco@gmail.com | E8: www.youtube.com/@afinco | F8: 57708117 | G8: 563000 | H8: 1505 | I8: sn2i8y2rv7Q | J8: buBZJ6iuO3o | K8: =VLOOKUP(B8,'Excluded(Nico)'!A:A,1,False) -> #REF! | L8: FALSE | M8: FALSE | N8: FALSE | P8: =VLOOKUP(A8,Grupos!B:E,4,FALSE) -> #REF!
A9: 0.0 | B9: UCN3mON2F9gMRdeLZTeWrugw | C9: Campos | D9: CONTEÚDO DE EAFC 24!Email de contato: camposplay2000@gmail.com | E9: www.youtube.com/@camposplay | F9: 110081289 | G9: 334000 | H9: 4259 | I9: 5avXXHISW4I | J9: ySn2aXvlkmM | K9: =VLOOKUP(B9,'Excluded(Nico)'!A:A,1,False) -> #REF! | L9: FALSE | M9: FALSE | N9: FALSE | P9: =VLOOKUP(A9,Grupos!B:E,4,FALSE) -> #REF!
A10: 0.0 | B10: UCgoYVT-QE3rgVy8j-bT-bBQ | C10: Rick Dalas | D10: Fala rapazeada, Eu sou o Ricardo, e estou começando esse Canal com conteúdo de qualidade, meu objetivo é trazer Vídeos todos os dias, conto com o apoio de todos, e É NÒISE-MAIL COMERCIAL: rickdalas98@gmail.com | E10: www.youtube.com/@rickdalas | F10: 66264222 | G10: 464000 | H10: 521 | I10: mxYUTj5BQoU | J10: 4ju8PZOxAu8 | K10: =VLOOKUP(B10,'Excluded(Nico)'!A:A,1,False) -> #REF! | L10: FALSE | M10: FALSE | N10: FALSE | P10: =VLOOKUP(A10,Grupos!B:E,4,FALSE) -> #REF!
A11: 0.0 | B11: UCjwNVw4nFUC86eXeVb9q1NQ | C11: Hobby Games BR | D11: Olá nós somos os irmãos Hobby ! Hariston e Richard .OBJETIVOS do canal Hobby Games BR :GAMEPLAY e TUTORIAL Para ANDROID e IOS . VLOGSRikinhoHaristonAqui você verá os melhores lançamentos para ANDROID e IOS incluindo : Dream League Soccer 2020 e PES 2020 além do FIFA 2020 para android e IOS | E11: www.youtube.com/@hobbygamesr | F11: 161334 | G11: 946000 | H11: 19 | I11: 6d7BC70ATVI | J11: aaq7Eoj5JjE | K11: =VLOOKUP(B11,'Excluded(Nico)'!A:A,1,False) -> #REF! | L11: FALSE | M11: FALSE | N11: FALSE | P11: =VLOOKUP(A11,Grupos!B:E,4,FALSE) -> #REF!
A12: 0.0 | B12: UCdw7bttktkE_5pr68ODsPyg | C12: Sentimento Tricolor | D12: Canal 100% dedicado ao Fluminense Football Club e sua torcida.Sou torcedor RAIZ, acompanho o FLUMINENSE pelas arquibancadas do Brasil desde os 10 anos de idade e quero que aqui você se sinta em casa. | E12: www.youtube.com/@sentimentotricolor | F12: 53216506 | G12: 139000 | H12: 2657 | I12: Rp_QNPgGshU | J12: vn_x5CHgLMM | K12: =VLOOKUP(B12,'Excluded(Nico)'!A:A,1,False) -> #REF! | L12: FALSE | M12: FALSE | N12: FALSE | P12: =VLOOKUP(A12,Grupos!B:E,4,FALSE) -> #REF!
A13: 0.0 | B13: UCNQcv9v2nZ118drS1QI1KTw | C13: Felipe Toys | D13: Seja bem vindo ao canal do Felipe Toys, aqui você encontrará os mais diversos tipos de videos , como por exemplo desafios de futebol, brincadeiras, desafios pessoais, vlogs e muito mais. | E13: www.youtube.com/@felipetoys | F13: 348318922 | G13: 1340000 | H13: 1490 | I13: XjrDY62L_5s | J13: EEWk13fWejU | K13: =VLOOKUP(B13,'Excluded(Nico)'!A:A,1,False) -> #REF! | L13: FALSE | M13: FALSE | N13: FALSE | P13: =VLOOKUP(A13,Grupos!B:E,4,FALSE) -> #REF!
A14: 0.0 | B14: UC99MSYUyI9FH-zwhjJe7iPA | C14: EI Games | D14: Canal oficial da TNT Sports com conteúdos exclusivos de games e eSports.Nos siga também no Instagram: https://www.instagram.com/eigames/ | E14: www.youtube.com/@gamesei | F14: 83441647 | G14: 858000 | H14: 3023 | I14: 18clsiw9-LU | J14: Kmn68HBTVLo | K14: =VLOOKUP(B14,'Excluded(Nico)'!A:A,1,False) -> #REF! | L14: FALSE | M14: FALSE | N14: FALSE | P14: =VLOOKUP(A14,Grupos!B:E,4,FALSE) -> #REF!
A15: 0.0 | B15: UCGDI3T92XGq6SKH-1LSb9Fw | C15: FIFA TRADE BRASIL | D15: Este é um canal para voce que quer aprender sobre o ea fc 24 ultimate team. Aqui voce vai encontrar videos sobre, pack opening, reviews de cartas, dicas de trade, dicas para fc ultimate team, dicas de gameplay ea fc 24, novidades do ea fc 24, noticias do ea fc 24, e gameplays do ea fc 24 em geral! Se inscreve ai! | E15: www.youtube.com/@fifatradebrasil | F15: 36823603 | G15: 177000 | H15: 3366 | I15: nW7jx0ccxL8 | J15: A5NvjDGZnVo | K15: =VLOOKUP(B15,'Excluded(Nico)'!A:A,1,False) -> #REF! | L15: FALSE | M15: FALSE | N15: FALSE | P15: =VLOOKUP(A15,Grupos!B:E,4,FALSE) -> #REF!
A16: 0.0 | B16: UCq5XoJwAieUDKEx4hAnlSiw | C16: Brunelli | D16: Oi, eu sou o Brunelli, comecei no youtube em 2011 e até hoje estou tentando ser alguém na plataforma, embarque comigo nessa jornada, você será muito bem vindo.-Redes Sociais: 📸 ➡️ https://www.instagram.com/BrunelliOFC/👍🏻 ➡️ https://web.facebook.com/BrunelliOFC/✖️ ➡️ https://twitter.com/BrunelliOFC-✉ Contato Comercial ➡️ brunelli.contato@gmail.com-Quer ajudar o canal?O Pix é ➡️ brunelli.contato@gmail.com | E16: www.youtube.com/@brunelliofc | F16: 30088663 | G16: 280000 | H16: 2000 | I16: lWdUdrYutp8 | J16: doPbQKMo7RI | K16: =VLOOKUP(B16,'Excluded(Nico)'!A:A,1,False) -> #REF! | L16: FALSE | M16: FALSE | N16: FALSE | P16: =VLOOKUP(A16,Grupos!B:E,4,FALSE) -> #REF!
A17: 0.0 | B17: UCPJ_tyPCmx1tqZtInpoiwBQ | C17: Walas RDG | D17: Olá eu sou Walace conhecido como Walas RDG, Aqui vocês vão ver vídeos meus de Free Fire.Inscreva-se no canal e ativa o sininho das notificações pra não perder os próximos vídeos.Instagram: @walacerdg | E17: www.youtube.com/@walasrdg | F17: 941 | G17: 152000 | H17: 5 | I17: yJxACaiUsDA | J17: baWfBh7l_XQ | K17: =VLOOKUP(B17,'Excluded(Nico)'!A:A,1,False) -> #REF! | L17: FALSE | M17: FALSE | N17: FALSE | P17: =VLOOKUP(A17,Grupos!B:E,4,FALSE) -> #REF!
A18: 0.0 | B18: UCtE5YlcDKHKkYpoOrdC8khw | C18: FKBrasil Football | D18: Treinos Específicos para atletas de Alto Rendimento ⚽🔥INSTRAGAM OFICIAL: @timefkbr | E18: www.youtube.com/@fkbrasilfootball | F18: 27176103 | G18: 160000 | H18: 896 | I18: BZCyabYwNGc | J18: GPowUR-qpc4 | K18: =VLOOKUP(B18,'Excluded(Nico)'!A:A,1,False) -> #REF! | L18: FALSE | M18: FALSE | N18: FALSE | P18: =VLOOKUP(A18,Grupos!B:E,4,FALSE) -> #REF!
... A27: 0.0 | B27: UCJoBd1P8G8-ePHdsEyE7LyQ | C27: Boxtoker | D27: Bem vindo a Boxtoker! Canal para quem gosta de colecionáveis. Figurinhas da copa, figurinhas de free fire, figurinhas do brasileirão, cartas pokémon entre outro! | E27: www.youtube.com/@boxtoker | F27: 81127024 | G27: 337000 | H27: 403 | I27: DtzOi6mwFoo | J27: FbZaMOY_PMo | K27: =VLOOKUP(B27,'Excluded(Nico)'!A:A,1,False) -> #REF! | L27: FALSE | M27: FALSE | N27: FALSE | P27: =VLOOKUP(A27,Grupos!B:E,4,FALSE) -> #REF!
A28: 0.0 | B28: UCVBuwnAxnK97iLF10nf_f_w | C28: Pelegrino1993 | E28: www.youtube.com/@pelegrino1993_ | F28: 64278463 | G28: 133000 | H28: 3320 | I28: bZBtHP-CHvc | J28: MBlmhDrCKp4 | K28: =VLOOKUP(B28,'Excluded(Nico)'!A:A,1,False) -> #REF! | L28: FALSE | M28: FALSE | N28: FALSE | P28: =VLOOKUP(A28,Grupos!B:E,4,FALSE) -> #REF!
A29: 0.0 | B29: UCUEvQXI_xaOX_ODHmKfAdbw | C29: TL FOOTBALL | D29: BEM VINDOS AO TL FOOTBALL !! ➖➖➖➖➖➖ ✓FUTEBOL✓MEMES ✓E MUITA ZOEIRA ESPORTIVA ➖➖➖➖➖➖''NÚMERO PARA PARCERIA 81998772035 '' INSCREVA-SE E NOS AJUDE PARA O CANAL CONTINUAR CRESCENDO! | E29: www.youtube.com/@tlfootball | F29: 1453632 | G29: 97700 | H29: 113 | I29: VjT1snyqDO0 | J29: ScrYXCGA3ew | K29: =VLOOKUP(B29,'Excluded(Nico)'!A:A,1,False) -> #REF! | L29: FALSE | M29: FALSE | N29: FALSE | P29: =VLOOKUP(A29,Grupos!B:E,4,FALSE) -> #REF!
A30: 0.0 | B30: UC7Xt068bxF9Ad2qdazUixOg | C30: Arthur Zenith23 | D30: Acompanhe minhas outras redes socias!🟣 Lives - https://www.twitch.tv/arthurzenith_23📸 Instagram - https://www.instagram.com/arthurzenith/📱 TikTok - https://www.tiktok.com/@arthurzenith23 | E30: www.youtube.com/@arthurzenith23 | F30: 753606 | G30: 62300 | H30: 342 | I30: bvsXkyvToCo | J30: Z1BchbrSCa0 | K30: =VLOOKUP(B30,'Excluded(Nico)'!A:A,1,False) -> #REF! | L30: FALSE | M30: FALSE | N30: FALSE | P30: =VLOOKUP(A30,Grupos!B:E,4,FALSE) -> #REF!
A31: 0.0 | B31: UCitQqEACHHE9nibANXS4lvg | C31: KBCA FC | D31: KBCA FC CHEGANDO! Quem tá junto ta junto, quem não ta junto também tá!Opa, trazendo novidades para vocês do FIFA MOBILE e também do novo ea fc mobile, todo dia com vídeos inéditos e que vão te entreter ou te dar dicas para voar no jogo com Trades, Bugs, Dicas de gameplay e muito mais!SEJA MEMBRO DO CANAL KBCA DO FIFA ATRAVÉS DESSE LINK:/www.youtube.com/channel/UCitQqEACHHE9nibANXS4lvg/joinSe gostou do conteúdo apresentado não esquece de dar aquela fortalecida no canal se inscrevendo, deixando os likes nos vídeos, comentando e virando membro!Se você quiser participar dos grupos grátis de WhatsApp do canal, os link estão logo abaixo! | E31: www.youtube.com/@kbcafc | F31: 22794696 | G31: 144000 | H31: 1318 | I31: LIzvTIJ113s | J31: 6BlB-k0nKO0 | K31: =VLOOKUP(B31,'Excluded(Nico)'!A:A,1,False) -> #REF! | L31: FALSE | M31: FALSE | N31: FALSE | P31: =VLOOKUP(A31,Grupos!B:E,4,FALSE) -> #REF!
A32: 0.0 | B32: UCjTU4tFZX4QI8Vwym6OvLCA | C32: Leo Frannco | D32: Motivação , tutoriais e tudo sobre futebol | E32: www.youtube.com/@leo_frannco | F32: 73715048 | G32: 217000 | H32: 386 | I32: WtW8EjwqkmU | J32: TgX67XOmFds | K32: =VLOOKUP(B32,'Excluded(Nico)'!A:A,1,False) -> #REF! | L32: FALSE | M32: FALSE | N32: FALSE | P32: =VLOOKUP(A32,Grupos!B:E,4,FALSE) -> #REF!
A33: 0.0 | B33: UCYRmbP6brUZG2Urxd5175lQ | C33: Felipe Tode | D33: quer ver muitos vídeos tops de FIFA 23? esse canal então é pra você !! Meu maior objetivo é ajudar as pessoas a esquecerem os problemas do dia, e poderem relaxar um pouco assistindo alguns desafios de futebol no FIFA. Sempre tem modo carreira treinador, jogador e também experimentos.de segunda a sexta os vídeos sempre saem as 11:00 hrs da manhã (horário de Brasília) e aí, bora acompanhar alguns vídeos tops de FIFA 23? ⚽​🏆​* contato comercial fetode85@gmail.com | E33: www.youtube.com/@todegames | F33: 787067 | G33: 115000 | H33: 40 | I33: 6QQTEXk2kyo | J33: 6ePY6tOlzFg | K33: =VLOOKUP(B33,'Excluded(Nico)'!A:A,1,False) -> #REF! | L33: FALSE | M33: FALSE | N33: FALSE | P33: =VLOOKUP(A33,Grupos!B:E,4,FALSE) -> #REF!
A34: 0.0 | B34: UCc-Z1eSOmw8XV4mrZ1tIh4A | C34: CANAL DO ZÉ | D34: Canal Oficial do ex- jogador Zé Roberto, com passagens e títulos por times do Brasil, Espanha, Alemanha e Emirados Árabes.Atualmente joga na equipe do Palmeiras (Brasil).Participou de duas Copas do Mundo: a de 1998, na França; e a de 2006, na Alemanha, quando integrou a seleção do torneio eleita pela Fifa e por duas vezes foi eleito o jogador da partida.Pela Seleção Brasileira foi: Campeão da Copa América em 1997 e 1999; Campeão da Copa das Confederações em 1997 e 2005.Acumula 85 exibições pela Seleção em pouco mais de 100 convocações. | E34: www.youtube.com/zerobertoficial | F34: 2682939 | G34: 114000 | H34: 148 | I34: H77NAR34UMQ | J34: TnIY67I8C2Q | K34: =VLOOKUP(B34,'Excluded(Nico)'!A:A,1,False) -> #REF! | L34: FALSE | M34: FALSE | N34: FALSE | P34: =VLOOKUP(A34,Grupos!B:E,4,FALSE) -> #REF!
A35: 0.0 | B35: UCXaCglVjtWfADvLOTzIRqvA | C35: Deyson GamePlays | D35: Olá meus amigos!!!Este é o canal oficial do Deyson GamePlays Meu canal é sobre jogabilidade de PES e FIFA. E talvez outros jogos ...Jogos reais do canal de jogos, que se inscrevem no meu canal,Desejo-lhe felicidade e um sorriso em seus rostos! obrigado meus amigos...Instagram: @deysongameplaysYoutube: deyson gameplaysFacebook: Deyson GamePlaysEnglishHello my friends!!!This is the official Deyson GamePlays channelMy channel is about PES and FIFA gameplay. And maybe other games...Real games from gaming channel, who subscribe to my channel,I wish you happiness and a smile on your faces! thank you my friends...Instagram: @deysongameplaysYoutube: deyson gameplaysFacebook: Deyson GamePlays | E35: www.youtube.com/@deysongameplays | F35: 5111147 | G35: 36200 | H35: 5058 | I35: zakiGE5AE3E | J35: GhkBXX7WGdo | K35: =VLOOKUP(B35,'Excluded(Nico)'!A:A,1,False) -> #REF! | L35: FALSE | M35: FALSE | N35: FALSE | P35: =VLOOKUP(A35,Grupos!B:E,4,FALSE) -> #REF!
A36: 0.0 | B36: UC1EKZWVFrlfLTB_eKujc-cw | C36: MUNDO FUT REACT 2.0 | E36: www.youtube.com/@mundofut2.0 | F36: 93622 | G36: 103000 | H36: 11 | I36: MOE9n2yP-rw | J36: 469xUEeL7so | K36: =VLOOKUP(B36,'Excluded(Nico)'!A:A,1,False) -> #REF! | L36: FALSE | M36: FALSE | N36: FALSE | P36: =VLOOKUP(A36,Grupos!B:E,4,FALSE) -> #REF!
A37: 0.0 | B37: UCQ4imW50ymEBRwmk6KtjEWQ | C37: FredVasquezBR | D37: Fred Vasquez e esse é meu Canal de FIFA/Jogos de Futebol em geral. Contato Comercial: assessoria@fredvasquez.comNo meu canal você encontra jogos de FIFA, de futebol em geral e vários modos de jogo como: EA Sports FC 24, FC 24 Novidades, Reconstruindo, FIFA 23 Modo Carreira, FIFA 23 BRASILEIRÃO MOD, FIFA 23 Experimentos, FUT DRAFT, FC 24 Ultimate Team, Rages, FIFA 23 Modo Carreira Jogador, outros JOGOS DE FUTEBOL. Gosto muito também de Álbum de Figurinhas da Copa de 2022, 2018 e muito mais! | E37: www.youtube.com/@fredvasquezbr | F37: 196009300 | G37: 953000 | H37: 1611 | I37: jyAItRXfiYs | J37: ta8RHmBfc6g | K37: =VLOOKUP(B37,'Excluded(Nico)'!A:A,1,False) -> #REF! | L37: FALSE | M37: FALSE | N37: FALSE | P37: =VLOOKUP(A37,Grupos!B:E,4,FALSE) -> #REF!
A38: 0.0 | B38: UCDei52NTESecMMVgBuOneVw | C38: SMU Games | D38: O pai vem ver o icon que eu tirei!Conteúdo sobre FIFA/EA Sports FC - Pack opening, Draft, Game Play! | E38: www.youtube.com/@smugames1 | F38: 90814463 | G38: 194000 | H38: 1104 | I38: PnjiKrGlxXg | J38: JEHDNJyvzjk | K38: =VLOOKUP(B38,'Excluded(Nico)'!A:A,1,False) -> #REF! | L38: FALSE | M38: FALSE | N38: FALSE | P38: =VLOOKUP(A38,Grupos!B:E,4,FALSE) -> #REF!
A39: 0.0 | B39: UCd82LTFa0Cv1PmVnba-9oTw | C39: ALEATORIOSKU | D39: Bem-vindo ao canal aleatoriosku, o canal dedicado aos amantes de duas grandes franquias de jogos: Minecraft e Blox Fruits. Aqui você encontrará vídeos cheios de emoção, aventuras e descobertas em um universo repleto de desafios e possibilidades.Seja explorando florestas encantadas, construindo cidades impressionantes ou enfrentando inimigos poderosos, estaremos juntos nessa jornada épica pelos mundos de Minecraft e Blox Fruits. Prepare-se para se maravilhar com paisagens incríveis, conhecer personagens cativantes e aprender estratégias e dicas que vão melhorar sua experiência de jogo.Além disso, compartilhamos atualizações sobre as últimas novidades e lançamentos dos jogos, mantendo você sempre informado sobre o que está por vir.Então, junte-se a nós e embarque nessa aventura cheia de criatividade, diversão e muita emoção. Siga nosso canal no Instagram: @aleatoriosku para ficar por dentro das últimas novidades, interagir com outros fãs e participar de sorteios | E39: www.youtube.com/@aleatoriosku | F39: 70149011 | G39: 241000 | H39: 400 | I39: 1u3XrKvJR48 | J39: PIapAXBcQ2g | K39: =VLOOKUP(B39,'Excluded(Nico)'!A:A,1,False) -> #REF! | L39: FALSE | M39: FALSE | N39: FALSE | P39: =VLOOKUP(A39,Grupos!B:E,4,FALSE) -> #REF!
A40: 0.0 | B40: UCFUkISZuKPjUBoycTuzsBCA | C40: Airton Silva | D40: Vídeos de FIFA e eFootball e gameplay de outros jogos com qualidade máxima :) | E40: www.youtube.com/@airtonsilvahd | F40: 160414823 | G40: 334000 | H40: 1271 | I40: hcBuvxpCilc | J40: TQo5o7Hvd9c | K40: =VLOOKUP(B40,'Excluded(Nico)'!A:A,1,False) -> #REF! | L40: FALSE | M40: FALSE | N40: FALSE | P40: =VLOOKUP(A40,Grupos!B:E,4,FALSE) -> #REF!
A41: 0.0 | B41: UCSoFN3x2gSC2KyCl4-pwwEg | C41: BOSS FC | D41: "🔴 Sejam bem-vindos ao Boss FC, antigo FIFA Champions RJ, Lucas Boss aqui, e este é um canal focado unicamente em produzir conteúdo sobre FIFA Mobile/EA FC Mobile. Confira nossas playlists, e encontre nossas principais séries!🔵🔵🔵 INSCREVA-SE NO MEU NOVO CANAL, O ""Boss Joga Aí:"" https://bit.ly/3unoplL 🔵🔵🔵 A ""Novela do Boss"" que mostra minha evolução na conta principal, a série ""Do Zero"", onde evoluo uma conta sem gastar nada, e sem fazer trade, ""Reviews"" e ""Análise de Defensores"", lista das melhores cartas, e de carta bons e baratos nas série ""Os Melhores"" e ""Bons e Baratos"", montando times diferentes e para inscritos na série ""FCRJ Squad"", testando contas de inscrito na série ""Os Melhores Elencos dos Inscritos"", e é claro, sempre que houver eventos novos tudo sobre eles, ""Dicas para Iniciciantes"", vídeos sobre formações e muitos outros, confiram!🔴 Contato Comercial: bossfcrj.contato@gmail 🔴🔴 Contato: (19) 98973-5984 🔴🔴 Criadores: Boss Brenner e Daudt🔴 " | E41: www.youtube.com/@boss-fc | F41: 70553044 | G41: 325000 | H41: 2610 | I41: cmex3g6KZZg | J41: l9ZjhoC8Jjk | K41: =VLOOKUP(B41,'Excluded(Nico)'!A:A,1,False) -> #REF! | L41: FALSE | M41: FALSE | N41: FALSE | P41: =VLOOKUP(A41,Grupos!B:E,4,FALSE) -> #REF!
A42: 0.0 | B42: UClikilDc0QBJxQ2jZXOYg0g | C42: Wendelllira11 | D42: Wendell Silva Lira, natural de Goiânia, nascido em 7 de janeiro de 1989, ex-futebolista profissional, ganhador do Prêmio Puskás de 2015-16, aos 27 anos de idade. Atualmente, streamer e pro player de Fifa pelo FLUXO na categoria de eSports. | E42: www.youtube.com/@wendelllira11 | F42: 70844345 | G42: 255000 | H42: 988 | I42: lxYMgxfLGjo | J42: -xeTkOI4OOY | K42: =VLOOKUP(B42,'Excluded(Nico)'!A:A,1,False) -> #REF! | L42: FALSE | M42: FALSE | N42: FALSE | P42: =VLOOKUP(A42,Grupos!B:E,4,FALSE) -> #REF!
A43: 0.0 | B43: UCrkSOd8m17PJK5yQ6RoFa6A | C43: RAFÃO | D43: Um pouco de Free Fire, jogos aleatórios e vlogs...Contato: rafao@krew.ggINSTAGRAM - @rafaotv | E43: www.youtube.com/@rafao_tv | F43: 447232048 | G43: 4490000 | H43: 1251 | I43: BBSLJq9DSqY | J43: K4dbeZT34QI | K43: =VLOOKUP(B43,'Excluded(Nico)'!A:A,1,False) -> #REF! | L43: FALSE | M43: FALSE | N43: FALSE | P43: =VLOOKUP(A43,Grupos!B:E,4,FALSE) -> #REF!
A44: 0.0 | B44: UCfKPSbHBWiUeYKFPlurpy9g | C44: Rodrigol FC | D44: Um canal de um viciado em FIFA, usuário de packs, apreciador dos dribles 5 estrelas e que adora chutar uma bola do meio da rua. Bora fazer gol comigo? | E44: www.youtube.com/@rodrigolfc | F44: 12341267 | G44: 124000 | H44: 682 | I44: scf_RRmWt8Y | J44: pAKP2-h0f2I | K44: =VLOOKUP(B44,'Excluded(Nico)'!A:A,1,False) -> #REF! | L44: FALSE | M44: FALSE | N44: FALSE | P44: =VLOOKUP(A44,Grupos!B:E,4,FALSE) -> #REF!
A45: 0.0 | B45: UCxKT_vmelBGqcpy1pya4nVQ | C45: morais jose | D45: FUTEBOL TOTAL (Morais José) - não sei qual critério que eles usam podemos perder um trabalho dedicado a todos vcs garanto eu sem nem um fim lucrativo só por diversão, eles notificam videos de um canal e outro não por isso digo não sei o critério. E mais videos com mais de ano que foi postado. vamos tentar seguir ok...TOTAL FOOTBALL (Morais José) - do not know what criteria they use may lose dedicated to all you guys I assure work without even making a profit just for fun, they notify videos from a channel and another not so I say do not know the criteria. And more videos over the year that was posted. ok ... let's try to followFÚTBOL TOTAL (Morais José) - no saben cuáles son los criterios que utilizan pueden perder dedicado a todos ustedes me aseguro de trabajo sin siquiera hacer un beneficio sólo por diversión, notifiquen los videos de un canal y el otro no, así que digo no conocen los criterios. Y más vídeos sobre el año en que fue publicado. ok ... vamos a tratar de seguir | E45: www.youtube.com/@moraisjose3312 | F45: 40788249 | G45: 98000 | H45: 1180 | I45: VmzwayCpbdw | J45: atE10bCUiY4 | K45: =VLOOKUP(B45,'Excluded(Nico)'!A:A,1,False) -> #REF! | L45: FALSE | M45: FALSE | N45: FALSE | P45: =VLOOKUP(A45,Grupos!B:E,4,FALSE) -> #REF!
A46: 0.0 | B46: UC2MZiyGuWl_w5FC2iF50hcA | C46: NOTAG | D46: 📩 Contato para parcerias e divulgações: notaggames@gmail.comMe siga em todas as redes sociais: @NotagFut | E46: www.youtube.com/@notagfut | F46: 57387592 | G46: 260000 | H46: 3629 | I46: jdwd48gRdaI | J46: DlAZMNDPD1M | K46: =VLOOKUP(B46,'Excluded(Nico)'!A:A,1,False) -> #REF! | L46: FALSE | M46: FALSE | N46: FALSE | P46: =VLOOKUP(A46,Grupos!B:E,4,FALSE) -> #REF!
A47: 0.0 | B47: UCiEyRxTPlsTg5hf6brK8S0A | C47: Higor Kamui | D47: Vídeos diários de Fifa MobileMais informações e redes sociais no meu Instagram @higorkamui | E47: www.youtube.com/@higorkamuii | F47: 197338851 | G47: 424000 | H47: 524 | I47: OWapKXHPPa8 | J47: -tmXmh9ereQ | K47: =VLOOKUP(B47,'Excluded(Nico)'!A:A,1,False) -> #REF! | L47: FALSE | M47: FALSE | N47: FALSE | P47: =VLOOKUP(A47,Grupos!B:E,4,FALSE) -> #REF!
A48: 0.0 | B48: UCVFzA6CL2m2Bvi5tyWWF_Mw | C48: Frankson BR | D48: Salve família🎮 sejam todos bem vindos ao nosso canal de FREE FIRE (GARENA) & de FC MOBILE ( FIFA) aqui você encontra vídeos curtos do Free Fire e conteúdos longos do Fifa... Espero que vocês curtam o canal Tmj sempre👍🏻❤️#rumoa100k🙏Me segue no instagram: @frankson__brReflexão...Quando você vencer na vida nunca esqueça de quem te apoiou! e o principal de tudo, nunca se esqueça de Deus! pois ele foi e sempre será o único que te apoiou de verdade na sua conquista, o único que não zombou de vc pelas costas quando vc estava correndo atrás dos seus sonhos q pra muitos era loucura! | E48: www.youtube.com/@franksonbr | F48: 6352717 | G48: 144000 | H48: 982 | I48: wyoYvkZFgWs | J48: Rv9S6fFqh-w | K48: =VLOOKUP(B48,'Excluded(Nico)'!A:A,1,False) -> #REF! | L48: FALSE | M48: FALSE | N48: FALSE | P48: =VLOOKUP(A48,Grupos!B:E,4,FALSE) -> #REF!
...
